Workbook

Sheet Base_Consolidada
A1: fato_id | B1: ies_nome | C1: campus_codigo | D1: edital_numero | E1: ano_vigencia | F1: fonte_dado | G1: publico_alvo | H1: eixo_pnaes | I1: modalidade_apoio | J1: valor_mensal_brl | K1: infraestrutura_disponivel | L1: total_vagas_ofertadas | M1: prazo_inscricao_dias | N1: criterios_elegibilidade
A2: 1 | B2: UFPB | C2: Campus IV - Litoral Norte (Mamanguape e Rio Tinto) | D2: 11/2026 (Retificado 1) | E2: 2026 | F2: Base CIAPE (db/csv/json) | G2: Unificado (ingressantes e veteranos) | H2: Alimentação | I2: Serviço Direto | J2: Serviço Direto | K2: Sim | L2: 30 | M2: 19 | N2: Renda familiar per capita <= 1 SM; RU ativo nas unidades de Rio Tinto (15 vagas) e Mamanguape (15 vagas)
A3: 2 | B3: UFPB | C3: Campus IV - Litoral Norte (Mamanguape e Rio Tinto) | D3: 11/2026 (Retificado 1) | E3: 2026 | F3: Base CIAPE (db/csv/json) | G3: Unificado (ingressantes e veteranos) | H3: Moradia | I3: Auxílio Financeiro (Auxílio Moradia) | J3: 700 | K3: Não | L3: 20 | M3: 19 | N3: Núcleo familiar fora do perímetro urbano de Mamanguape/Rio Tinto; sem imóvel próprio/financiado na cidade sede
A4: 3 | B4: UFPB | C4: Campus IV - Litoral Norte (Mamanguape e Rio Tinto) | D4: 11/2026 (Retificado 1) | E4: 2026 | F4: Base CIAPE (db/csv/json) | G4: Unificado (ingressantes e veteranos) | H4: Moradia | I4: Vaga Física - Infraestrutura (Residência Universitária) | J4: 680 | K4: Sim | L4: 4 | M4: 19 | N4: 2 vagas masculinas + 2 femininas; parcela única inicial de R$500,00; mesmos requisitos geográficos da Moradia
A5: 4 | B5: UFPB | C5: Campus IV - Litoral Norte (Mamanguape e Rio Tinto) | D5: 11/2026 (Retificado 1) | E5: 2026 | F5: Base CIAPE (db/csv/json) | G5: Unificado (ingressantes e veteranos) | H5: Transporte | I5: Auxílio Financeiro (Faixa 1) | J5: 125 | K5: Não | L5: 15 | M5: 19 | N5: Residência em Mamanguape, Rio Tinto, Baía da Traição ou Marcação
A6: 5 | B6: UFPB | C6: Campus IV - Litoral Norte (Mamanguape e Rio Tinto) | D6: 11/2026 (Retificado 1) | E6: 2026 | F6: Base CIAPE (db/csv/json) | G6: Unificado (ingressantes e veteranos) | H6: Transporte | I6: Auxílio Financeiro (Faixa 2) | J6: 250 | K6: Não | L6: 10 | M6: 19 | N6: Municípios da Faixa 2 (ex.: Capim, Cuité de Mamanguape, Jacaraú)
A7: 6 | B7: UFPB | C7: Campus IV - Litoral Norte (Mamanguape e Rio Tinto) | D7: 11/2026 (Retificado 1) | E7: 2026 | F7: Base CIAPE (db/csv/json) | G7: Unificado (ingressantes e veteranos) | H7: Transporte | I7: Auxílio Financeiro (Faixa 3) | J7: 586 | K7: Não | L7: 5 | M7: 19 | N7: Municípios da Faixa 3 (ex.: João Pessoa, Bayeux, Cabedelo, Guarabira)
A8: 7 | B8: UFPB | C8: Campus I - João Pessoa e Santa Rita | D8: 12/2025 (Retificado 2) | E8: 2025 | F8: Base CIAPE (db/csv/json) | G8: Unificado (ingressantes e veteranos) | H8: Alimentação | I8: Serviço Direto (Restaurante Universitário) | J8: Serviço Direto | K8: Sim | L8: 100 | M8: 34 | N8: Não matriculado em cursos sediados em Mangabeira ou Santa Rita
A9: 8 | B9: UFPB | C9: Campus I - João Pessoa e Santa Rita | D9: 12/2025 (Retificado 2) | E9: 2025 | F9: Base CIAPE (db/csv/json) | G9: Unificado (ingressantes e veteranos) | H9: Alimentação | I9: Auxílio Financeiro (Auxílio Alimentação) | J9: 360 | K9: Não | L9: 15 | M9: 34 | N9: Exclusivo para matriculados em Mangabeira ou Santa Rita (unidades sem RU)
A10: 9 | B10: UFPB | C10: Campus I - João Pessoa e Santa Rita | D10: 12/2025 (Retificado 2) | E10: 2025 | F10: Base CIAPE (db/csv/json) | G10: Unificado (ingressantes e veteranos) | H10: Moradia | I10: Auxílio Financeiro (Auxílio Moradia) | J10: 700 | K10: Não | L10: 50 | M10: 34 | N10: Núcleo familiar fora do perímetro urbano de João Pessoa, Santa Rita, Bayeux e Cabedelo
A11: 10 | B11: UFPB | C11: Campus I - João Pessoa e Santa Rita | D11: 12/2025 (Retificado 2) | E11: 2025 | F11: Base CIAPE (db/csv/json) | G11: Unificado (ingressantes e veteranos) | H11: Moradia | I11: Vaga Física - Infraestrutura (RUMF - Masculina) | J11: 400 | K11: Sim | L11: 2 | M11: 34 | N11: Parcela única inicial de R$400,00; mesmos requisitos geográficos da Moradia
A12: 11 | B12: UFPB | C12: Campus I - João Pessoa e Santa Rita | D12: 12/2025 (Retificado 2) | E12: 2025 | F12: Base CIAPE (db/csv/json) | G12: Unificado (ingressantes e veteranos) | H12: Moradia | I12: Vaga Física - Infraestrutura (RUFET - Feminina) | J12: 580 | K12: Sim | L12: 3 | M12: 34 | N12: Uso exclusivo feminino; parcela única inicial de R$400,00
A13: 12 | B13: UFPB | C13: Campus I - João Pessoa e Santa Rita | D13: 12/2025 (Retificado 2) | E13: 2025 | F13: Base CIAPE (db/csv/json) | G13: Unificado (ingressantes e veteranos) | H13: Transporte | I13: Auxílio Financeiro (Faixa 1) | J13: 108 | K13: Não | L13: 30 | M13: 34 | N13: Residência no município da sede do curso (João Pessoa ou Santa Rita)
A14: 13 | B14: UFPB | C14: Campus I - João Pessoa e Santa Rita | D14: 12/2025 (Retificado 2) | E14: 2025 | F14: Base CIAPE (db/csv/json) | G14: Unificado (ingressantes e veteranos) | H14: Transporte | I14: Auxílio Financeiro (Faixa 2) | J14: 216 | K14: Não | L14: 15 | M14: 34 | N14: Municípios da Faixa 2 (ex.: Bayeux, Cabedelo, Conde)
A15: 14 | B15: UFPB | C15: Campus I - João Pessoa e Santa Rita | D15: 12/2025 (Retificado 2) | E15: 2025 | F15: Base CIAPE (db/csv/json) | G15: Unificado (ingressantes e veteranos) | H15: Transporte | I15: Auxílio Financeiro (Faixa 3) | J15: 586 | K15: Não | L15: 5 | M15: 34 | N15: Municípios da Faixa 3 (ex.: Mamanguape, Rio Tinto, Sapé)
A16: 15 | B16: UFPB | C16: Campus II - Areia | D16: 13/2025 (Retificado 1) | E16: 2025 | F16: Base CIAPE (db/csv/json) | G16: Unificado (ingressantes e veteranos) | H16: Alimentação | I16: Serviço Direto (Restaurante Universitário) | J16: Serviço Direto | K16: Sim | L16: 25 | M16: 34 | N16: Matriculado em qualquer unidade acadêmica do Campus II
A17: 16 | B17: UFPB | C17: Campus II - Areia | D17: 13/2025 (Retificado 1) | E17: 2025 | F17: Base CIAPE (db/csv/json) | G17: Unificado (ingressantes e veteranos) | H17: Moradia | I17: Auxílio Financeiro (Auxílio Moradia) | J17: 700 | K17: Não | L17: 15 | M17: 34 | N17: Núcleo familiar fora do perímetro urbano de Areia
A18: 17 | B18: UFPB | C18: Campus II - Areia | D18: 13/2025 (Retificado 1) | E18: 2025 | F18: Base CIAPE (db/csv/json) | G18: Unificado (ingressantes e veteranos) | H18: Moradia | I18: Vaga Física - Infraestrutura (Residência Universitária) | J18: 400 | K18: Sim | L18: 5 | M18: 34 | N18: 3 vagas masculinas + 2 femininas; parcela única inicial de R$400,00
A19: 18 | B19: UFPB | C19: Campus II - Areia | D19: 13/2025 (Retificado 1) | E19: 2025 | F19: Base CIAPE (db/csv/json) | G19: Unificado (ingressantes e veteranos) | H19: Transporte | I19: Auxílio Financeiro (Faixa 1) | J19: 108 | K19: Não | L19: 5 | M19: 34 | N19: Residência no município de Areia
A20: 19 | B20: UFPB | C20: Campus II - Areia | D20: 13/2025 (Retificado 1) | E20: 2025 | F20: Base CIAPE (db/csv/json) | G20: Unificado (ingressantes e veteranos) | H20: Transporte | I20: Auxílio Financeiro (Faixa 2) | J20: 216 | K20: Não | L20: 3 | M20: 34 | N20: Municípios da Faixa 2 (ex.: Alagoa Grande, Esperança, Remígio)
A21: 20 | B21: UFPB | C21: Campus II - Areia | D21: 13/2025 (Retificado 1) | E21: 2025 | F21: Base CIAPE (db/csv/json) | G21: Unificado (ingressantes e veteranos) | H21: Transporte | I21: Auxílio Financeiro (Faixa 3) | J21: 586 | K21: Não | L21: 2 | M21: 34 | N21: Municípios da Faixa 3 (ex.: Campina Grande, Guarabira, Sapé)
A22: 21 | B22: UFPB | C22: Campus III - Bananeiras | D22: 14/2025 (Retificado 2) | E22: 2025 | F22: PDF Edital PRAPE 14/2025 (Retificado 2) | G22: Unificado (ingressantes e veteranos) | H22: Alimentação | I22: Serviço Direto (Restaurante Universitário) | J22: Serviço Direto | K22: Sim | L22: 25 | M22: 34 | N22: Estar matriculado em qualquer unidade acadêmica do Campus III
A23: 22 | B23: UFPB | C23: Campus III - Bananeiras | D23: 14/2025 (Retificado 2) | E23: 2025 | F23: PDF Edital PRAPE 14/2025 (Retificado 2) | G23: Unificado (ingressantes e veteranos) | H23: Moradia | I23: Auxílio Financeiro (Auxílio Moradia) | J23: 700 | K23: Não | L23: 15 | M23: 34 | N23: Núcleo familiar fora do perímetro urbano de Bananeiras ou Solânea; sem imóvel próprio/financiado na cidade sede
A24: 23 | B24: UFPB | C24: Campus III - Bananeiras | D24: 14/2025 (Retificado 2) | E24: 2025 | F24: PDF Edital PRAPE 14/2025 (Retificado 2) | G24: Unificado (ingressantes e veteranos) | H24: Moradia | I24: Vaga Física - Infraestrutura (Residência Universitária) | J24: 400 | K24: Sim | L24: 2 | M24: 34 | N24: 1 vaga masculina + 1 feminina; parcela única inicial de R$400,00; mesmos requisitos geográficos da Moradia
A25: 24 | B25: UFPB | C25: Campus III - Bananeiras | D25: 14/2025 (Retificado 2) | E25: 2025 | F25: PDF Edital PRAPE 14/2025 (Retificado 2) | G25: Unificado (ingressantes e veteranos) | H25: Transporte | I25: Auxílio Financeiro (Faixa 1) | J25: 108 | K25: Não | L25: 5 | M25: 34 | N25: Residência em Bananeiras, Belém, Borborema ou Solânea
A26: 25 | B26: UFPB | C26: Campus III - Bananeiras | D26: 14/2025 (Retificado 2) | E26: 2025 | F26: PDF Edital PRAPE 14/2025 (Retificado 2) | G26: Unificado (ingressantes e veteranos) | H26: Transporte | I26: Auxílio Financeiro (Faixa 2) | J26: 216 | K26: Não | L26: 3 | M26: 34 | N26: Municípios da Faixa 2 (ex.: Arara, Dona Inês, Guarabira, Pirpirituba)
A27: 26 | B27: UFPB | C27: Campus III - Bananeiras | D27: 14/2025 (Retificado 2) | E27: 2025 | F27: PDF Edital PRAPE 14/2025 (Retificado 2) | G27: Unificado (ingressantes e veteranos) | H27: Transporte | I27: Auxílio Financeiro (Faixa 3) | J27: 586 | K27: Não | L27: 2 | M27: 34 | N27: Municípios da Faixa 3 (ex.: Alagoa Grande, Areia, Sapé, Remígio)
A28: 27 | B28: UFPB | C28: Campus III - Bananeiras | D28: 14/2025 (Retificado 2) | E28: 2025 | F28: PDF Edital PRAPE 14/2025 (Retificado 2) | G28: Unificado (ingressantes e veteranos) | H28: Creche/Pré-escolar | I28: Auxílio Financeiro (Auxílio Pré-escolar) | J28: 250 | K28: Não | L28: 5 | M28: 34 | N28: Comprovação de coabitação com filho menor de 6 anos (Declaração Anexo I + certidão de nascimento)
A29: 28 | B29: UFPB | C29: Campus IV - Litoral Norte (Mamanguape e Rio Tinto) | D29: 15/2025 (Retificado 1) | E29: 2025 | F29: PDF Edital PRAPE 15/2025 (Retificado 1) | G29: Unificado (ingressantes e veteranos) | H29: Alimentação | I29: Serviço Direto (Restaurante Universitário - Rio Tinto) | J29: Serviço Direto | K29: Sim | L29: 15 | M29: 34 | N29: Matriculado em qualquer unidade acadêmica do Campus IV
A30: 29 | B30: UFPB | C30: Campus IV - Litoral Norte (Mamanguape e Rio Tinto) | D30: 15/2025 (Retificado 1) | E30: 2025 | F30: PDF Edital PRAPE 15/2025 (Retificado 1) | G30: Unificado (ingressantes e veteranos) | H30: Alimentação | I30: Serviço Direto (Restaurante Universitário - Mamanguape) | J30: Serviço Direto | K30: Sim | L30: 10 | M30: 34 | N30: Matriculado em qualquer unidade acadêmica do Campus IV
A31: 30 | B31: UFPB | C31: Campus IV - Litoral Norte (Mamanguape e Rio Tinto) | D31: 15/2025 (Retificado 1) | E31: 2025 | F31: PDF Edital PRAPE 15/2025 (Retificado 1) | G31: Unificado (ingressantes e veteranos) | H31: Moradia | I31: Auxílio Financeiro (Auxílio Moradia) | J31: 700 | K31: Não | L31: 15 | M31: 34 | N31: Núcleo familiar fora do perímetro urbano de Mamanguape ou Rio Tinto
A32: 31 | B32: UFPB | C32: Campus IV - Litoral Norte (Mamanguape e Rio Tinto) | D32: 15/2025 (Retificado 1) | E32: 2025 | F32: PDF Edital PRAPE 15/2025 (Retificado 1) | G32: Unificado (ingressantes e veteranos) | H32: Moradia | I32: Vaga Física - Infraestrutura (Residência Universitária) | J32: 580 | K32: Sim | L32: 2 | M32: 34 | N32: 1 vaga masculina + 1 feminina; parcela única inicial de R$400,00; mesmos requisitos geográficos da Moradia
A33: 32 | B33: UFPB | C33: Campus IV - Litoral Norte (Mamanguape e Rio Tinto) | D33: 15/2025 (Retificado 1) | E33: 2025 | F33: PDF Edital PRAPE 15/2025 (Retificado 1) | G33: Unificado (ingressantes e veteranos) | H33: Transporte | I33: Auxílio Financeiro (Faixa 1) | J33: 108 | K33: Não | L33: 5 | M33: 34 | N33: Residência em Mamanguape, Rio Tinto, Baía da Traição ou Marcação
A34: 33 | B34: UFPB | C34: Campus IV - Litoral Norte (Mamanguape e Rio Tinto) | D34: 15/2025 (Retificado 1) | E34: 2025 | F34: PDF Edital PRAPE 15/2025 (Retificado 1) | G34: Unificado (ingressantes e veteranos) | H34: Transporte | I34: Auxílio Financeiro (Faixa 2) | J34: 216 | K34: Não | L34: 3 | M34: 34 | N34: Municípios da Faixa 2 (ex.: Capim, Cuité de Mamanguape, Jacaraú)
A35: 34 | B35: UFPB | C35: Campus IV - Litoral Norte (Mamanguape e Rio Tinto) | D35: 15/2025 (Retificado 1) | E35: 2025 | F35: PDF Edital PRAPE 15/2025 (Retificado 1) | G35: Unificado (ingressantes e veteranos) | H35: Transporte | I35: Auxílio Financeiro (Faixa 3) | J35: 586 | K35: Não | L35: 2 | M35: 34 | N35: Municípios da Faixa 3 (ex.: João Pessoa, Bayeux, Cabedelo, Guarabira)
A36: 35 | B36: UFPB | C36: Campus IV - Litoral Norte (Mamanguape e Rio Tinto) | D36: 15/2025 (Retificado 1) | E36: 2025 | F36: PDF Edital PRAPE 15/2025 (Retificado 1) | G36: Unificado (ingressantes e veteranos) | H36: Creche/Pré-escolar | I36: Auxílio Financeiro (Auxílio Pré-escolar) | J36: 250 | K36: Não | L36: 5 | M36: 34 | N36: Comprovação de coabitação com filho menor de 6 anos (Declaração Anexo I + certidão de nascimento)
A37: 36 | B37: UFPB | C37: Campus I - João Pessoa e Santa Rita | D37: 08/2026 (Retificado 1) | E37: 2026 | F37: PDF Edital PRAPE 08/2026 (Retificado 1) | G37: Unificado (ingressantes e veteranos) | H37: Alimentação | I37: Serviço Direto (Restaurante Universitário) | J37: Serviço Direto | K37: Sim | L37: 100 | M37: 19 | N37: Não matriculado em cursos sediados em Mangabeira ou Santa Rita
A38: 37 | B38: UFPB | C38: Campus I - João Pessoa e Santa Rita | D38: 08/2026 (Retificado 1) | E38: 2026 | F38: PDF Edital PRAPE 08/2026 (Retificado 1) | G38: Unificado (ingressantes e veteranos) | H38: Alimentação | I38: Auxílio Financeiro (Auxílio Alimentação) | J38: 360 | K38: Não | L38: 20 | M38: 19 | N38: Exclusivo para matriculados em Mangabeira ou Santa Rita (unidades sem RU)
A39: 38 | B39: UFPB | C39: Campus I - João Pessoa e Santa Rita | D39: 08/2026 (Retificado 1) | E39: 2026 | F39: PDF Edital PRAPE 08/2026 (Retificado 1) | G39: Unificado (ingressantes e veteranos) | H39: Moradia | I39: Auxílio Financeiro (Auxílio Moradia) | J39: 700 | K39: Não | L39: 50 | M39: 19 | N39: Núcleo familiar fora do perímetro urbano de João Pessoa, Santa Rita, Bayeux e Cabedelo; sem imóvel próprio/financiado na cidade sede
A40: 39 | B40: UFPB | C40: Campus I - João Pessoa e Santa Rita | D40: 08/2026 (Retificado 1) | E40: 2026 | F40: PDF Edital PRAPE 08/2026 (Retificado 1) | G40: Unificado (ingressantes e veteranos) | H40: Moradia | I40: Vaga Física - Infraestrutura (RUMF - Masculina) | J40: 500 | K40: Sim | L40: 4 | M40: 19 | N40: Parcela única inicial de R$500,00; mesmos requisitos geográficos da Moradia
...

Sheet Resumo_Vagas
A1: Campus | B1: Edital | C1: Alimentação | D1: Moradia | E1: Transporte | F1: Creche/Pré-escolar | G1: Total Geral
A2: Campus IV - Litoral Norte (Mamanguape e Rio Tinto) | B2: 11/2026 (Retificado 1) | C2: =SUMIFS(Base_Consolidada!$L$2:$L$45,Base_Consolidada!$C$2:$C$45,$A2,Base_Consolidada!$D$2:$D$45,$B2,Base_Consolidada!$H$2:$H$45,C1) -> 30 | D2: =SUMIFS(Base_Consolidada!$L$2:$L$45,Base_Consolidada!$C$2:$C$45,$A2,Base_Consolidada!$D$2:$D$45,$B2,Base_Consolidada!$H$2:$H$45,D1) -> 24 | E2: =SUMIFS(Base_Consolidada!$L$2:$L$45,Base_Consolidada!$C$2:$C$45,$A2,Base_Consolidada!$D$2:$D$45,$B2,Base_Consolidada!$H$2:$H$45,E1) -> 30 | F2: =SUMIFS(Base_Consolidada!$L$2:$L$45,Base_Consolidada!$C$2:$C$45,$A2,Base_Consolidada!$D$2:$D$45,$B2,Base_Consolidada!$H$2:$H$45,F1) -> 0 | G2: =SUM(C2:F2) -> 84
A3: Campus I - João Pessoa e Santa Rita | B3: 12/2025 (Retificado 2) | C3: =SUMIFS(Base_Consolidada!$L$2:$L$45,Base_Consolidada!$C$2:$C$45,$A3,Base_Consolidada!$D$2:$D$45,$B3,Base_Consolidada!$H$2:$H$45,C1) -> 115 | D3: =SUMIFS(Base_Consolidada!$L$2:$L$45,Base_Consolidada!$C$2:$C$45,$A3,Base_Consolidada!$D$2:$D$45,$B3,Base_Consolidada!$H$2:$H$45,D1) -> 55 | E3: =SUMIFS(Base_Consolidada!$L$2:$L$45,Base_Consolidada!$C$2:$C$45,$A3,Base_Consolidada!$D$2:$D$45,$B3,Base_Consolidada!$H$2:$H$45,E1) -> 50 | F3: =SUMIFS(Base_Consolidada!$L$2:$L$45,Base_Consolidada!$C$2:$C$45,$A3,Base_Consolidada!$D$2:$D$45,$B3,Base_Consolidada!$H$2:$H$45,F1) -> 0 | G3: =SUM(C3:F3) -> 220
A4: Campus II - Areia | B4: 13/2025 (Retificado 1) | C4: =SUMIFS(Base_Consolidada!$L$2:$L$45,Base_Consolidada!$C$2:$C$45,$A4,Base_Consolidada!$D$2:$D$45,$B4,Base_Consolidada!$H$2:$H$45,C1) -> 25 | D4: =SUMIFS(Base_Consolidada!$L$2:$L$45,Base_Consolidada!$C$2:$C$45,$A4,Base_Consolidada!$D$2:$D$45,$B4,Base_Consolidada!$H$2:$H$45,D1) -> 20 | E4: =SUMIFS(Base_Consolidada!$L$2:$L$45,Base_Consolidada!$C$2:$C$45,$A4,Base_Consolidada!$D$2:$D$45,$B4,Base_Consolidada!$H$2:$H$45,E1) -> 10 | F4: =SUMIFS(Base_Consolidada!$L$2:$L$45,Base_Consolidada!$C$2:$C$45,$A4,Base_Consolidada!$D$2:$D$45,$B4,Base_Consolidada!$H$2:$H$45,F1) -> 0 | G4: =SUM(C4:F4) -> 55
A5: Campus III - Bananeiras | B5: 14/2025 (Retificado 2) | C5: =SUMIFS(Base_Consolidada!$L$2:$L$45,Base_Consolidada!$C$2:$C$45,$A5,Base_Consolidada!$D$2:$D$45,$B5,Base_Consolidada!$H$2:$H$45,C1) -> 25 | D5: =SUMIFS(Base_Consolidada!$L$2:$L$45,Base_Consolidada!$C$2:$C$45,$A5,Base_Consolidada!$D$2:$D$45,$B5,Base_Consolidada!$H$2:$H$45,D1) -> 17 | E5: =SUMIFS(Base_Consolidada!$L$2:$L$45,Base_Consolidada!$C$2:$C$45,$A5,Base_Consolidada!$D$2:$D$45,$B5,Base_Consolidada!$H$2:$H$45,E1) -> 10 | F5: =SUMIFS(Base_Consolidada!$L$2:$L$45,Base_Consolidada!$C$2:$C$45,$A5,Base_Consolidada!$D$2:$D$45,$B5,Base_Consolidada!$H$2:$H$45,F1) -> 5 | G5: =SUM(C5:F5) -> 57
A6: Campus IV - Litoral Norte (Mamanguape e Rio Tinto) | B6: 15/2025 (Retificado 1) | C6: =SUMIFS(Base_Consolidada!$L$2:$L$45,Base_Consolidada!$C$2:$C$45,$A6,Base_Consolidada!$D$2:$D$45,$B6,Base_Consolidada!$H$2:$H$45,C1) -> 25 | D6: =SUMIFS(Base_Consolidada!$L$2:$L$45,Base_Consolidada!$C$2:$C$45,$A6,Base_Consolidada!$D$2:$D$45,$B6,Base_Consolidada!$H$2:$H$45,D1) -> 17 | E6: =SUMIFS(Base_Consolidada!$L$2:$L$45,Base_Consolidada!$C$2:$C$45,$A6,Base_Consolidada!$D$2:$D$45,$B6,Base_Consolidada!$H$2:$H$45,E1) -> 10 | F6: =SUMIFS(Base_Consolidada!$L$2:$L$45,Base_Consolidada!$C$2:$C$45,$A6,Base_Consolidada!$D$2:$D$45,$B6,Base_Consolidada!$H$2:$H$45,F1) -> 5 | G6: =SUM(C6:F6) -> 57
A7: Campus I - João Pessoa e Santa Rita | B7: 08/2026 (Retificado 1) | C7: =SUMIFS(Base_Consolidada!$L$2:$L$45,Base_Consolidada!$C$2:$C$45,$A7,Base_Consolidada!$D$2:$D$45,$B7,Base_Consolidada!$H$2:$H$45,C1) -> 120 | D7: =SUMIFS(Base_Consolidada!$L$2:$L$45,Base_Consolidada!$C$2:$C$45,$A7,Base_Consolidada!$D$2:$D$45,$B7,Base_Consolidada!$H$2:$H$45,D1) -> 60 | E7: =SUMIFS(Base_Consolidada!$L$2:$L$45,Base_Consolidada!$C$2:$C$45,$A7,Base_Consolidada!$D$2:$D$45,$B7,Base_Consolidada!$H$2:$H$45,E1) -> 60 | F7: =SUMIFS(Base_Consolidada!$L$2:$L$45,Base_Consolidada!$C$2:$C$45,$A7,Base_Consolidada!$D$2:$D$45,$B7,Base_Consolidada!$H$2:$H$45,F1) -> 5 | G7: =SUM(C7:F7) -> 245
A8: TOTAL GERAL (todos os campi) | C8: =SUM(C2:C7) -> 340 | D8: =SUM(D2:D7) -> 193 | E8: =SUM(E2:E7) -> 170 | F8: =SUM(F2:F7) -> 15 | G8: =SUM(G2:G7) -> 718

Sheet Fontes_e_Metodologia
A1: Este arquivo consolida os dados de auxílios PNAES/PRAPE/UFPB por campus e edital.
A3: Fonte de dados | B3: Descrição | C3: Arquivos originais
A4: Base CIAPE (db/csv/json) | B4: Base estruturada fornecida (ciape.db, modelo estrela: Dim_Instituicao, Dim_Campus, Dim_Tempo, Fato_Permanencia). Cobre Campus I (12/2025), Campus II (13/2025) e Campus IV (11/2026). | C4: ciape.db / ciape_dados_pnaes.csv / ciape_dados_pnaes.json
A5: PDF Edital PRAPE 14/2025 (Retificado 2) | B5: Edital completo lido e extraído manualmente. Cobre Campus III - Bananeiras. | C5: RETIFICADO-2-Edital-14-2025-CAMPUS-III_Selecao-auxilios-2025_1.pdf
A6: PDF Edital PRAPE 15/2025 (Retificado 1) | B6: Edital completo lido e extraído manualmente. Cobre Campus IV - Litoral Norte, versão 2025 (anterior à retificação 11/2026 já presente na base CIAPE). | C6: RETIFICADO-1-Edital-15-2025-CAMPUS-IV_Selecao-auxilios-2025_1.pdf
A7: PDF Edital PRAPE 08/2026 (Retificado 1) | B7: Edital completo lido e extraído manualmente. Cobre Campus I - João Pessoa e Santa Rita, versão 2026 (sucessor do Edital 12/2025 já presente na base CIAPE - citado no próprio edital como referência de aproveitamento de pontuação). | C7: retificado-1-Edital-08-2026-CAMPUS-I_Selecao-auxilios-2026_1.pdf
A9: Observações importantes:
A10: 1) O Campus IV possui DOIS registros distintos: Edital 15/2025 (PDF) e Edital 11/2026 (base CIAPE). Entre as duas edições o RU passou de 25 para 30 vagas totais, o Auxílio Moradia de 15 para 20 vagas, e os valores de Transporte das Faixas 1 e 2 aumentaram (R$108→R$125 e R$216→R$250).
A11: 2) O Campus I agora também possui DOIS registros: Edital 12/2025 (base CIAPE) e Edital 08/2026 (PDF, que cita e sucede o 12/2025). Principais mudanças: Auxílio Alimentação 15→20 vagas; Residência Universitária RUMF (masc.) 2→4 vagas e R$400→R$500, RUFET (fem.) 3→6 vagas e R$580→R$680; parcela única inicial R$400→R$500; Transporte Faixa 1 mantido em vagas (30) mas valor R$108→R$125, Faixa 2 15→20 vagas e R$216→R$250, Faixa 3 5→10 vagas (valor R$586 mantido); e o Auxílio Pré-escolar (5 vagas, R$250) passou a constar explicitamente - não havia registro desse eixo para o Campus I na base CIAPE 2025, o que pode refletir uma lacuna na extração original dos dados, e não necessariamente a ausência do auxílio naquele edital.
A12: 3) Trate registros do mesmo campus com números de edital diferentes como pontos no tempo (retificações/reedições anuais), não como duplicatas a serem removidas.
A14: Este arquivo é atualizado automaticamente sempre que um novo edital é enviado para leitura.
